<?xml version="1.0"?>
<robot xmlns:xacro="https://www.ros.org/wiki">

  <!-- colores -->
  <material name="white">
    <color rgba="1 1 1 1"/>
  </material>

  <material name="blue">
    <color rgba="0.2 0.2 1 1"/>
  </material>

  <material name="black">
    <color rgba="0 0 0 1"/>
  </material>


  <link name="base_link">
  </link>

  <!-- chasiss -->
  <joint name="chassis_joint" type="fixed">
    <parent link="base_link"/>
    <child link="chassis"/>
    <origin xyz="-0.1 0 0"/>
  </joint>


  <link name="chassis">
    <visual>
      <origin xyz="0.15 0 0.075"/>
      <geometry>
        <box size="0.3 0.3 0.15"/>
      </geometry>
      <material name="white"/>
    </visual>
    <collision>
      <origin xyz="0.15 0 0.075"/>
      <geometry>
        <box size="0.3 0.3 0.15"/>
      </geometry>
    </collision>
    <inertial>
      <origin xyz="0.15 0 0.075" rpy="0 0 0"/>
      <mass value="0.5"/>
      <inertia ixx="0.0046875" ixy="0.0" ixz="0.0" iyy="0.0046875" iyz="0.0" izz="0.0075"/>
    </inertial>
  </link>

  <gazebo reference="chassis">
    <material>Gazebo/White</material>
  </gazebo>


  <!-- left_wheel -->
  <joint name="left_wheel_joint" type="continuous">
    <parent link="base_link"/>
    <child link="left_wheel"/>
    <origin xyz="0 0.175 0" rpy="-1.57 0 0"/>
    <axis xyz="0 0 1"/>
  </joint>

  <link name="left_wheel">
    <visual>
      <geometry>
        <cylinder radius="0.05" length="0.04"/>
      </geometry>
      <material name="blue"/>
    </visual>
    <collision>
      <geometry>
        <cylinder radius="0.05" length="0.04"/>
      </geometry>
    </collision>
    <inertial>
      <origin xyz="0 0 0" rpy="0 0 0"/>
      <mass value="0.1"/>
      <inertia ixx="0.0000758" ixy="0.0" ixz="0.0" iyy="0.0000758" iyz="0.0" izz="0.000125"/>
    </inertial>
  </link>


  <gazebo reference="left_wheel">
    <material>Gazebo/Blue</material>
  </gazebo>


  <!-- right_wheel -->
  <joint name="right_wheel_joint" type="continuous">
    <parent link="base_link"/>
    <child link="right_wheel"/>
    <origin xyz="0 -0.175 0" rpy="1.57 0 0"/>
    <axis xyz="0 0 -1"/>
  </joint>

  <link name="right_wheel">
    <visual>
      <geometry>
        <cylinder radius="0.05" length="0.04"/>
      </geometry>
      <material name="blue"/>
    </visual>
    <collision>
      <geometry>
        <cylinder radius="0.05" length="0.04"/>
      </geometry>
    </collision>
    <inertial>
      <origin xyz="0 0 0" rpy="0 0 0"/>
      <mass value="0.1"/>
      <inertia ixx="0.0000758" ixy="0.0" ixz="0.0" iyy="0.0000758" iyz="0.0" izz="0.000125"/>
    </inertial>
  </link>

  <gazebo reference="right_wheel">
    <material>Gazebo/Blue</material>
  </gazebo>


  <!-- caster_wheel -->
  <joint name="caster_wheel_joint" type="fixed">
      <parent link="chassis"/>
      <child link="caster_wheel"/>      
      <origin xyz="0.24 0 0"/>
  </joint>

  <link name="caster_wheel">
    <visual>
      <geometry>
        <sphere radius="0.05"/>
       </geometry>
       <material name="black"/>
    </visual>
    <collision>
      <geometry>
        <sphere radius="0.05"/>
      </geometry>
    </collision>
    <inertial>
      <origin xyz="0 0 0" rpy="0 0 0"/>
      <mass value="0.1"/>
      <inertia ixx="0.0001" ixy="0.0" ixz="0.0" iyy="0.0001" iyz="0.0" izz="0.0001"/>
    </inertial>
  </link>

  <gazebo reference="caster_wheel">
    <material>Gazebo/Black</material>
    <mu1>0.001</mu1>
    <mu2>0.001</mu2>
  </gazebo>

</robot>
